<sdf version='1.6'>
  <model name='ALPHRED_V3'>
    <link name='Body'>
      <pose frame=''>0 0 0 0 -0 0</pose>
      <inertial>
        <pose frame=''>-0.013271 0.028004 0.014992 0 -0 0</pose>
        <mass>5.00941</mass>
        <inertia>
          <ixx>0.0549422</ixx>
          <ixy>0.00650932</ixy>
          <ixz>0.010503</ixz>
          <iyy>0.04806</iyy>
          <iyz>-0.00643363</iyz>
          <izz>0.0551648</izz>
        </inertia>
      </inertial>
      <collision name='Body_collision'>
        <pose frame=''>0 0 0 0 -0 0</pose>
        <geometry>
          <mesh>
            <scale>1 1 1</scale>
            <uri>model://ALPHRED_V3/meshes/collision/Body_collision.STL</uri>
          </mesh>
        </geometry>
      </collision>
      <visual name='Body_visual'>
        <pose frame=''>0 0 0 0 -0 0</pose>
        <geometry>
          <mesh>
            <scale>1 1 1</scale>
            <uri>model://ALPHRED_V3/meshes/Body.STL</uri>
          </mesh>
        </geometry>
      </visual>
    </link>
    <link name='Limb1_shoulder'>
      <pose frame=''>0 -0.1375 -0.067922 -0 -0 -1.5708</pose>
      <inertial>
        <pose frame=''>0.06023 3.3e-05 0.000776 0 -0 0</pose>
        <mass>0.986087</mass>
        <inertia>
          <ixx>0.00211105</ixx>
          <ixy>1.9537e-06</ixy>
          <ixz>4.58862e-05</ixz>
          <iyy>0.00307989</iyy>
          <iyz>-4.11738e-06</iyz>
          <izz>0.003987</izz>
        </inertia>
      </inertial>
      <collision name='Limb1_shoulder_collision'>
        <pose frame=''>0 0 0 0 -0 0</pose>
        <geometry>
          <mesh>
            <scale>1 1 1</scale>
            <uri>model://ALPHRED_V3/meshes/collision/Limb1_shoulder_collision.STL</uri>
          </mesh>
        </geometry>
      </collision>
      <visual name='Limb1_shoulder_visual'>
        <pose frame=''>0 0 0 0 -0 0</pose>
        <geometry>
          <mesh>
            <scale>1 1 1</scale>
            <uri>model://ALPHRED_V3/meshes/Limb1_shoulder.STL</uri>
          </mesh>
        </geometry>
      </visual>
    </link>
    <joint name='J01' type='revolute'>
      <child>Limb1_shoulder</child>
      <parent>Body</parent>
      <axis>
        <xyz>-0 -0 1</xyz>
        <limit>
          <lower>-1.57075</lower>
          <upper>1.57075</upper>
          <effort>52.8</effort>
        </limit>
        <dynamics>
          <spring_reference>0</spring_reference>
          <spring_stiffness>0</spring_stiffness>
        </dynamics>
        <use_parent_model_frame>1</use_parent_model_frame>
      </axis>
    </joint>
    <link name='Limb1_femur'>
      <pose frame=''>-0 -0.24 -0.067922 -1.5708 -0 -1.5708</pose>
      <inertial>
        <pose frame=''>0.120274 -0.001463 8.5e-05 0 -0 0</pose>
        <mass>0.463366</mass>
        <inertia>
          <ixx>0.000219084</ixx>
          <ixy>-5.50094e-05</ixy>
          <ixz>5.63609e-06</ixz>
          <iyy>0.00760546</iyy>
          <iyz>9.39721e-07</iyz>
          <izz>0.00769739</izz>
        </inertia>
      </inertial>
      <collision name='Limb1_femur_collision'>
        <pose frame=''>0 0 0 0 -0 0</pose>
        <geometry>
          <mesh>
            <scale>1 1 1</scale>
            <uri>model://ALPHRED_V3/meshes/collision/Limb1_femur_collision.STL</uri>
          </mesh>
        </geometry>
      </collision>
      <visual name='Limb1_femur_visual'>
        <pose frame=''>0 0 0 0 -0 0</pose>
        <geometry>
          <mesh>
            <scale>1 1 1</scale>
            <uri>model://ALPHRED_V3/meshes/Limb1_femur.STL</uri>
          </mesh>
        </geometry>
      </visual>
    </link>
    <joint name='J02' type='revolute'>
      <child>Limb1_femur</child>
      <parent>Limb1_shoulder</parent>
      <axis>
        <xyz>1 4e-06 4e-06</xyz>
        <limit>
          <lower>-1.7</lower>
          <upper>1.70</upper>
          <effort>52.8</effort>
        </limit>
        <dynamics>
          <spring_reference>0</spring_reference>
          <spring_stiffness>0</spring_stiffness>
        </dynamics>
        <use_parent_model_frame>1</use_parent_model_frame>
      </axis>
    </joint>
    <link name='Limb1_tibia'>
      <pose frame=''>0.001248 -0.59 -0.067922 -1.5708 -0 -1.5708</pose>
      <inertial>
        <pose frame=''>0.196225 -5.3e-05 -0.006039 0 -0 0</pose>
        <mass>0.427427</mass>
        <inertia>
          <ixx>0.000340708</ixx>
          <ixy>1.92636e-06</ixy>
          <ixz>-0.000256494</ixz>
          <iyy>0.00618998</iyy>
          <iyz>2.01874e-07</iyz>
          <izz>0.00589658</izz>
        </inertia>
      </inertial>
      <collision name='Limb1_tibia_collision'>
        <pose frame=''>0 0 0 0 -0 0</pose>
        <geometry>
          <mesh>
            <scale>1 1 1</scale>
            <uri>model://ALPHRED_V3/meshes/collision/Limb1_tibia_collision.STL</uri>
          </mesh>
        </geometry>
      </collision>
      <collision name='Limb1_tibia_fixed_joint_lump__Limb1_foot_collision_1'>
        <pose frame=''>0.32375 0 -0.00125 0 -1.57079 -1.57079</pose>
        <geometry>
          <mesh>
            <scale>1 1 1</scale>
            <uri>model://ALPHRED_V3/meshes/Limb1_foot.STL</uri>
          </mesh>
        </geometry>
        <surface>
          <contact>
            <ode>
              <min_depth>0.001</min_depth>
            </ode>
          </contact>
          <friction>
            <ode>
              <mu>1.0</mu>
              <mu2>1.0</mu2>
              <slip1>0.0</slip1>
              <slip2>0.0</slip2>
            </ode>
          </friction>
        </surface>
      </collision>
      <visual name='Limb1_tibia_visual'>
        <pose frame=''>0 0 0 0 -0 0</pose>
        <geometry>
          <mesh>
            <scale>1 1 1</scale>
            <uri>model://ALPHRED_V3/meshes/Limb1_tibia.STL</uri>
          </mesh>
        </geometry>
      </visual>
      <visual name='Limb1_tibia_fixed_joint_lump__Limb1_foot_visual_1'>
        <pose frame=''>0.32375 0 -0.00125 0 -1.57079 -1.57079</pose>
        <geometry>
          <mesh>
            <scale>1 1 1</scale>
            <uri>model://ALPHRED_V3/meshes/Limb1_foot.STL</uri>
          </mesh>
        </geometry>
      </visual>
      <sensor name='ALPHRED_LIMB1_CONTACT' type='contact'>
        <plugin name="limb1_contact_plugin" filename="libcontact.so"/>
        <contact>
          <collision>Limb1_tibia_fixed_joint_lump__Limb1_foot_collision_1</collision>
        </contact>
      </sensor>
    </link>
    <joint name='J03' type='revolute'>
      <child>Limb1_tibia</child>
      <parent>Limb1_femur</parent>
      <axis>
        <xyz>1 4e-06 4e-06</xyz>
        <limit>
          <lower>-2.79</lower>
          <upper>2.79</upper>
          <effort>52.8</effort>
        </limit>
        <dynamics>
          <spring_reference>0</spring_reference>
          <spring_stiffness>0</spring_stiffness>
        </dynamics>
        <use_parent_model_frame>1</use_parent_model_frame>
      </axis>
    </joint>
    <link name='Limb2_shoulder'>
      <pose frame=''>0.1375 0 -0.067922 -0 0 -0</pose>
      <inertial>
        <pose frame=''>0.06023 3.3e-05 0.000776 0 -0 0</pose>
        <mass>0.986087</mass>
        <inertia>
          <ixx>0.00211105</ixx>
          <ixy>1.95352e-06</ixy>
          <ixz>4.58861e-05</ixz>
          <iyy>0.00307989</iyy>
          <iyz>-4.11727e-06</iyz>
          <izz>0.00398699</izz>
        </inertia>
      </inertial>
      <collision name='Limb2_shoulder_collision'>
        <pose frame=''>0 0 0 0 -0 0</pose>
        <geometry>
          <mesh>
            <scale>1 1 1</scale>
            <uri>model://ALPHRED_V3/meshes/collision/Limb2_shoulder_collision.STL</uri>
          </mesh>
        </geometry>
      </collision>
      <visual name='Limb2_shoulder_visual'>
        <pose frame=''>0 0 0 0 -0 0</pose>
        <geometry>
          <mesh>
            <scale>1 1 1</scale>
            <uri>model://ALPHRED_V3/meshes/Limb2_shoulder.STL</uri>
          </mesh>
        </geometry>
      </visual>
    </link>
    <joint name='J04' type='revolute'>
      <child>Limb2_shoulder</child>
      <parent>Body</parent>
      <axis>
        <xyz>-0 -0 1</xyz>
        <limit>
          <lower>-1.57075</lower>
          <upper>1.57075</upper>
          <effort>52.8</effort>
        </limit>
        <dynamics>
          <spring_reference>0</spring_reference>
          <spring_stiffness>0</spring_stiffness>
        </dynamics>
        <use_parent_model_frame>1</use_parent_model_frame>
      </axis>
    </joint>
    <link name='Limb2_femur'>
      <pose frame=''>0.24 -0 -0.067922 -1.5708 -0 -0</pose>
      <inertial>
        <pose frame=''>0.120274 -0.001463 8.5e-05 0 -0 0</pose>
        <mass>0.463365</mass>
        <inertia>
          <ixx>0.000219084</ixx>
          <ixy>-5.50094e-05</ixy>
          <ixz>5.63611e-06</ixz>
          <iyy>0.00760546</iyy>
          <iyz>9.39721e-07</iyz>
          <izz>0.00769739</izz>
        </inertia>
      </inertial>
      <collision name='Limb2_femur_collision'>
        <pose frame=''>0 0 0 0 -0 0</pose>
        <geometry>
          <mesh>
            <scale>1 1 1</scale>
            <uri>model://ALPHRED_V3/meshes/collision/Limb2_femur_collision.STL</uri>
          </mesh>
        </geometry>
      </collision>
      <visual name='Limb2_femur_visual'>
        <pose frame=''>0 0 0 0 -0 0</pose>
        <geometry>
          <mesh>
            <scale>1 1 1</scale>
            <uri>model://ALPHRED_V3/meshes/Limb2_femur.STL</uri>
          </mesh>
        </geometry>
      </visual>
    </link>
    <joint name='J05' type='revolute'>
      <child>Limb2_femur</child>
      <parent>Limb2_shoulder</parent>
      <axis>
        <xyz>-0 1 4e-06</xyz>
        <limit>
          <lower>-1.70</lower>
          <upper>1.70</upper>
          <effort>52.8</effort>
        </limit>
        <dynamics>
          <spring_reference>0</spring_reference>
          <spring_stiffness>0</spring_stiffness>
        </dynamics>
        <use_parent_model_frame>1</use_parent_model_frame>
      </axis>
    </joint>
    <link name='Limb2_tibia'>
      <pose frame=''>0.59 0.00125 -0.067922 -1.5708 -0 -0</pose>
      <inertial>
        <pose frame=''>0.196979 5.3e-05 0.003812 0 -0 0</pose>
        <mass>0.427202</mass>
        <inertia>
          <ixx>0.00033956</ixx>
          <ixy>-1.90939e-06</ixy>
          <ixz>0.0002808</ixz>
          <iyy>0.00625146</iyy>
          <iyz>2.05451e-07</iyz>
          <izz>0.00595921</izz>
        </inertia>
      </inertial>
      <collision name='Limb2_tibia_collision'>
        <pose frame=''>0 0 0 0 -0 0</pose>
        <geometry>
          <mesh>
            <scale>1 1 1</scale>
            <uri>model://ALPHRED_V3/meshes/collision/Limb2_tibia_collision.STL</uri>
          </mesh>
        </geometry>
      </collision>
      <collision name='Limb2_tibia_fixed_joint_lump__Limb2_foot_collision_1'>
        <pose frame=''>0.32375 0 -0.00125 3.14159 0 1.5708</pose>
        <geometry>
          <mesh>
            <scale>1 1 1</scale>
            <uri>model://ALPHRED_V3/meshes/Limb2_foot.STL</uri>
          </mesh>
        </geometry>
        <surface>
          <contact>
            <ode>
              <min_depth>0.001</min_depth>
            </ode>
          </contact>
          <friction>
            <ode>
              <mu>1.0</mu>
              <mu2>1.0</mu2>
              <slip1>0.0</slip1>
              <slip2>0.0</slip2>
            </ode>
          </friction>
        </surface>
      </collision>
      <visual name='Limb2_tibia_visual'>
        <pose frame=''>0 0 0 0 -0 0</pose>
        <geometry>
          <mesh>
            <scale>1 1 1</scale>
            <uri>model://ALPHRED_V3/meshes/Limb2_tibia.STL</uri>
          </mesh>
        </geometry>
      </visual>
      <visual name='Limb2_tibia_fixed_joint_lump__Limb2_foot_visual_1'>
        <pose frame=''>0.32375 0 -0.00125 3.14159 0 1.5708</pose>
        <geometry>
          <mesh>
            <scale>1 1 1</scale>
            <uri>model://ALPHRED_V3/meshes/Limb2_foot.STL</uri>
          </mesh>
        </geometry>
      </visual>
      <sensor name='ALPHRED_LIMB2_CONTACT' type='contact'>
        <plugin name="limb2_contact_plugin" filename="libcontact.so"/>
        <contact>
          <collision>Limb2_tibia_fixed_joint_lump__Limb2_foot_collision_1</collision>
        </contact>
      </sensor>
    </link>
    <joint name='J06' type='revolute'>
      <child>Limb2_tibia</child>
      <parent>Limb2_femur</parent>
      <axis>
        <xyz>0 1 -4e-06</xyz>
        <limit>
          <lower>-2.79</lower>
          <upper>2.79</upper>
          <effort>52.8</effort>
        </limit>
        <dynamics>
          <spring_reference>0</spring_reference>
          <spring_stiffness>0</spring_stiffness>
        </dynamics>
        <use_parent_model_frame>1</use_parent_model_frame>
      </axis>
    </joint>
    <link name='Limb3_shoulder'>
      <pose frame=''>0 0.1375 -0.067922 0 0 1.5708</pose>
      <inertial>
        <pose frame=''>0.06023 3.3e-05 0.000776 0 -0 0</pose>
        <mass>0.986087</mass>
        <inertia>
          <ixx>0.00211105</ixx>
          <ixy>1.9536e-06</ixy>
          <ixz>4.58862e-05</ixz>
          <iyy>0.00307989</iyy>
          <iyz>-4.11736e-06</iyz>
          <izz>0.003987</izz>
        </inertia>
      </inertial>
      <collision name='Limb3_shoulder_collision'>
        <pose frame=''>0 0 0 0 -0 0</pose>
        <geometry>
          <mesh>
            <scale>1 1 1</scale>
            <uri>model://ALPHRED_V3/meshes/collision/Limb3_shoulder_collision.STL</uri>
          </mesh>
        </geometry>
      </collision>
      <visual name='Limb3_shoulder_visual'>
        <pose frame=''>0 0 0 0 -0 0</pose>
        <geometry>
          <mesh>
            <scale>1 1 1</scale>
            <uri>model://ALPHRED_V3/meshes/Limb3_shoulder.STL</uri>
          </mesh>
        </geometry>
      </visual>
    </link>
    <joint name='J07' type='revolute'>
      <child>Limb3_shoulder</child>
      <parent>Body</parent>
      <axis>
        <xyz>0 -0 1</xyz>
        <limit>
          <lower>-1.57075</lower>
          <upper>1.57075</upper>
          <effort>52.8</effort>
        </limit>
        <dynamics>
          <spring_reference>0</spring_reference>
          <spring_stiffness>0</spring_stiffness>
        </dynamics>
        <use_parent_model_frame>1</use_parent_model_frame>
      </axis>
    </joint>
    <link name='Limb3_femur'>
      <pose frame=''>-0 0.24 -0.067922 -1.5708 -0 1.5708</pose>
      <inertial>
        <pose frame=''>0.120274 -0.001463 8.5e-05 0 -0 0</pose>
        <mass>0.463366</mass>
        <inertia>
          <ixx>0.000219084</ixx>
          <ixy>-5.50094e-05</ixy>
          <ixz>5.6361e-06</ixz>
          <iyy>0.00760546</iyy>
          <iyz>9.39721e-07</iyz>
          <izz>0.00769739</izz>
        </inertia>
      </inertial>
      <collision name='Limb3_femur_collision'>
        <pose frame=''>0 0 0 0 -0 0</pose>
        <geometry>
          <mesh>
            <scale>1 1 1</scale>
            <uri>model://ALPHRED_V3/meshes/collision/Limb3_femur_collision.STL</uri>
          </mesh>
        </geometry>
      </collision>
      <visual name='Limb3_femur_visual'>
        <pose frame=''>0 0 0 0 -0 0</pose>
        <geometry>
          <mesh>
            <scale>1 1 1</scale>
            <uri>model://ALPHRED_V3/meshes/Limb3_femur.STL</uri>
          </mesh>
        </geometry>
      </visual>
    </link>
    <joint name='J08' type='revolute'>
      <child>Limb3_femur</child>
      <parent>Limb3_shoulder</parent>
      <axis>
        <xyz>-1 4e-06 4e-06</xyz>
        <limit>
          <lower>-1.70</lower>
          <upper>1.70</upper>
          <effort>52.8</effort>
        </limit>
        <dynamics>
          <spring_reference>0</spring_reference>
          <spring_stiffness>0</spring_stiffness>
        </dynamics>
        <use_parent_model_frame>1</use_parent_model_frame>
      </axis>
    </joint>
    <link name='Limb3_tibia'>
      <pose frame=''>-0.001252 0.59 -0.067922 -1.5708 0 1.5708</pose>
      <inertial>
        <pose frame=''>0.196877 -5.3e-05 -0.006039 0 -0 0</pose>
        <mass>0.427427</mass>
        <inertia>
          <ixx>0.000340708</ixx>
          <ixy>1.91165e-06</ixy>
          <ixz>-0.00025783</ixz>
          <iyy>0.00626094</iyy>
          <iyz>2.01868e-07</iyz>
          <izz>0.00596754</izz>
        </inertia>
      </inertial>
      <collision name='Limb3_tibia_collision'>
        <pose frame=''>0 0 0 0 -0 0</pose>
        <geometry>
          <mesh>
            <scale>1 1 1</scale>
            <uri>model://ALPHRED_V3/meshes/collision/Limb3_tibia_collision.STL</uri>
          </mesh>
        </geometry>
      </collision>
      <collision name='Limb3_tibia_fixed_joint_lump__Limb3_foot_collision_1'>
        <pose frame=''>0.32375 0 -0.00125 -3.14159 1.57079 1.57079</pose>
        <geometry>
          <mesh>
            <scale>1 1 1</scale>
            <uri>model://ALPHRED_V3/meshes/Limb3_foot.STL</uri>
          </mesh>
        </geometry>
        <surface>
          <contact>
            <ode>
              <min_depth>0.001</min_depth>
            </ode>
          </contact>
          <friction>
            <ode>
              <mu>1.0</mu>
              <mu2>1.0</mu2>
              <slip1>0.0</slip1>
              <slip2>0.0</slip2>
            </ode>
          </friction>
        </surface>
      </collision>
      <visual name='Limb3_tibia_visual'>
        <pose frame=''>0 0 0 0 -0 0</pose>
        <geometry>
          <mesh>
            <scale>1 1 1</scale>
            <uri>model://ALPHRED_V3/meshes/Limb3_tibia.STL</uri>
          </mesh>
        </geometry>
      </visual>
      <visual name='Limb3_tibia_fixed_joint_lump__Limb3_foot_visual_1'>
        <pose frame=''>0.32375 0 -0.00125 -3.14159 1.57079 1.57079</pose>
        <geometry>
          <mesh>
            <scale>1 1 1</scale>
            <uri>model://ALPHRED_V3/meshes/Limb3_foot.STL</uri>
          </mesh>
        </geometry>
      </visual>
      <sensor name='ALPHRED_LIMB3_CONTACT' type='contact'>
        <plugin name="limb3_contact_plugin" filename="libcontact.so"/>
        <contact>
          <collision>Limb3_tibia_fixed_joint_lump__Limb3_foot_collision_1</collision>
        </contact>
      </sensor>
    </link>
    <joint name='J09' type='revolute'>
      <child>Limb3_tibia</child>
      <parent>Limb3_femur</parent>
      <axis>
        <xyz>-1 4e-06 4e-06</xyz>
        <limit>
          <lower>-2.79</lower>
          <upper>2.79</upper>
          <effort>52.8</effort>
        </limit>
        <dynamics>
          <spring_reference>0</spring_reference>
          <spring_stiffness>0</spring_stiffness>
        </dynamics>
        <use_parent_model_frame>1</use_parent_model_frame>
      </axis>
    </joint>
    <link name='Limb4_shoulder'>
      <pose frame=''>-0.1375 0 -0.067922 0 0 -3.14159</pose>
      <inertial>
        <pose frame=''>0.06023 3.3e-05 0.000776 0 -0 0</pose>
        <mass>0.986087</mass>
        <inertia>
          <ixx>0.00211105</ixx>
          <ixy>1.95346e-06</ixy>
          <ixz>4.58862e-05</ixz>
          <iyy>0.00307989</iyy>
          <iyz>-4.11726e-06</iyz>
          <izz>0.003987</izz>
        </inertia>
      </inertial>
      <collision name='Limb4_shoulder_collision'>
        <pose frame=''>0 0 0 0 -0 0</pose>
        <geometry>
          <mesh>
            <scale>1 1 1</scale>
            <uri>model://ALPHRED_V3/meshes/collision/Limb4_shoulder_collision.STL</uri>
          </mesh>
        </geometry>
      </collision>
      <visual name='Limb4_shoulder_visual'>
        <pose frame=''>0 0 0 0 -0 0</pose>
        <geometry>
          <mesh>
            <scale>1 1 1</scale>
            <uri>model://ALPHRED_V3/meshes/Limb4_shoulder.STL</uri>
          </mesh>
        </geometry>
      </visual>
    </link>
    <joint name='J10' type='revolute'>
      <child>Limb4_shoulder</child>
      <parent>Body</parent>
      <axis>
        <xyz>0 -0 1</xyz>
        <limit>
          <lower>-1.57075</lower>
          <upper>1.57075</upper>
          <effort>52.8</effort>
        </limit>
        <dynamics>
          <spring_reference>0</spring_reference>
          <spring_stiffness>0</spring_stiffness>
        </dynamics>
        <use_parent_model_frame>1</use_parent_model_frame>
      </axis>
    </joint>
    <link name='Limb4_femur'>
      <pose frame=''>-0.24 -1e-06 -0.067922 -1.5708 -0 -3.14159</pose>
      <inertial>
        <pose frame=''>0.120274 -0.001463 8.5e-05 0 -0 0</pose>
        <mass>0.463366</mass>
        <inertia>
          <ixx>0.000219084</ixx>
          <ixy>-5.50094e-05</ixy>
          <ixz>5.6361e-06</ixz>
          <iyy>0.00760546</iyy>
          <iyz>9.39721e-07</iyz>
          <izz>0.00769739</izz>
        </inertia>
      </inertial>
      <collision name='Limb4_femur_collision'>
        <pose frame=''>0 0 0 0 -0 0</pose>
        <geometry>
          <mesh>
            <scale>1 1 1</scale>
            <uri>model://ALPHRED_V3/meshes/collision/Limb4_femur_collision.STL</uri>
          </mesh>
        </geometry>
      </collision>
      <visual name='Limb4_femur_visual'>
        <pose frame=''>0 0 0 0 -0 0</pose>
        <geometry>
          <mesh>
            <scale>1 1 1</scale>
            <uri>model://ALPHRED_V3/meshes/Limb4_femur.STL</uri>
          </mesh>
        </geometry>
      </visual>
    </link>
    <joint name='J11' type='revolute'>
      <child>Limb4_femur</child>
      <parent>Limb4_shoulder</parent>
      <axis>
        <xyz>-7e-06 -1 4e-06</xyz>
        <limit>
          <lower>-1.70</lower>
          <upper>1.70</upper>
          <effort>52.8</effort>
        </limit>
        <dynamics>
          <spring_reference>0</spring_reference>
          <spring_stiffness>0</spring_stiffness>
        </dynamics>
        <use_parent_model_frame>1</use_parent_model_frame>
      </axis>
    </joint>
    <link name='Limb4_tibia'>
      <pose frame=''>-0.59 -0.001253 -0.067922 -1.5708 -0 -3.14159</pose>
      <inertial>
        <pose frame=''>0.196979 5.3e-05 0.003812 0 -0 0</pose>
        <mass>0.427201</mass>
        <inertia>
          <ixx>0.00033956</ixx>
          <ixy>-1.90943e-06</ixy>
          <ixz>0.0002808</ixz>
          <iyy>0.00625146</iyy>
          <iyz>2.05437e-07</iyz>
          <izz>0.00595921</izz>
        </inertia>
      </inertial>
      <collision name='Limb4_tibia_collision'>
        <pose frame=''>0 0 0 0 -0 0</pose>
        <geometry>
          <mesh>
            <scale>1 1 1</scale>
            <uri>model://ALPHRED_V3/meshes/collision/Limb4_tibia_collision.STL</uri>
          </mesh>
        </geometry>
      </collision>
      <collision name='Limb4_tibia_fixed_joint_lump__Limb4_foot_collision_1'>
        <pose frame=''>0.32375 0 -0.00125 0 -0 -1.5708</pose>
        <geometry>
          <mesh>
            <scale>1 1 1</scale>
            <uri>model://ALPHRED_V3/meshes/Limb4_foot.STL</uri>
          </mesh>
        </geometry>
        <surface>
          <contact>
            <ode>
              <min_depth>0.001</min_depth>
            </ode>
          </contact>
          <friction>
            <ode>
              <mu>1.0</mu>
              <mu2>1.0</mu2>
              <slip1>0.0</slip1>
              <slip2>0.0</slip2>
            </ode>
          </friction>
        </surface>
      </collision>
      <visual name='Limb4_tibia_visual'>
        <pose frame=''>0 0 0 0 -0 0</pose>
        <geometry>
          <mesh>
            <scale>1 1 1</scale>
            <uri>model://ALPHRED_V3/meshes/Limb4_tibia.STL</uri>
          </mesh>
        </geometry>
      </visual>
      <visual name='Limb4_tibia_fixed_joint_lump__Limb4_foot_visual_1'>
        <pose frame=''>0.32375 0 -0.00125 0 -0 -1.5708</pose>
        <geometry>
          <mesh>
            <scale>1 1 1</scale>
            <uri>model://ALPHRED_V3/meshes/Limb4_foot.STL</uri>
          </mesh>
        </geometry>
      </visual>
      <sensor name='ALPHRED_LIMB4_CONTACT' type='contact'>
        <plugin name="limb4_contact_plugin" filename="libcontact.so"/>
        <contact>
          <collision>Limb4_tibia_fixed_joint_lump__Limb4_foot_collision_1</collision>
        </contact>
      </sensor>
    </link>
    <joint name='J12' type='revolute'>
      <child>Limb4_tibia</child>
      <parent>Limb4_femur</parent>
      <axis>
        <xyz>7e-06 -1 4e-06</xyz>
        <limit>
          <lower>-2.79</lower>
          <upper>2.79</upper>
          <effort>52.8</effort>
        </limit>
        <dynamics>
          <spring_reference>0</spring_reference>
          <spring_stiffness>0</spring_stiffness>
        </dynamics>
        <use_parent_model_frame>1</use_parent_model_frame>
      </axis>
    </joint>
  </model>
</sdf>
