<robot
  name="ALPHRED">
  <link
    name="Body">
    <inertial>
      <origin
        xyz="0.019985 0.0012164 0.087551"
        rpy="0 0 0" />
      <mass
        value="5.0094" />
      <inertia
        ixx="0.044551"
        ixy="0.0001113"
        ixz="-0.0091521"
        iyy="0.065557"
        iyz="5.3517E-05"
        izz="0.04806" />
    </inertial>
    <visual>
      <origin
        xyz="0 0 0"
        rpy="0 0 0" />
      <geometry>
        <mesh
          filename="package://ALPHRED/meshes/Body.STL" />
      </geometry>
      <material
        name="">
        <color
          rgba="0.75294 0.75294 0.75294 1" />
      </material>
    </visual>
    <collision>
      <origin
        xyz="0 0 0"
        rpy="0 0 0" />
      <geometry>
        <mesh
          filename="package://ALPHRED/meshes/Body.STL" />
      </geometry>
    </collision>
  </link>
  <link
    name="Limb1_shoulder">
    <inertial>
      <origin
        xyz="0.060229 3.2881E-05 0.0007757"
        rpy="0 0 0" />
      <mass
        value="0.98609" />
      <inertia
        ixx="0.0021111"
        ixy="1.9537E-06"
        ixz="4.5886E-05"
        iyy="0.0030799"
        iyz="-4.1174E-06"
        izz="0.003987" />
    </inertial>
    <visual>
      <origin
        xyz="0 0 0"
        rpy="0 0 0" />
      <geometry>
        <mesh
          filename="package://ALPHRED/meshes/Limb1_shoulder.STL" />
      </geometry>
      <material
        name="">
        <color
          rgba="0.75294 0.75294 0.75294 1" />
      </material>
    </visual>
    <collision>
      <origin
        xyz="0 0 0"
        rpy="0 0 0" />
      <geometry>
        <mesh
          filename="package://ALPHRED/meshes/Limb1_shoulder.STL" />
      </geometry>
    </collision>
  </link>
  <joint
    name="J1"
    type="revolute">
    <origin
      xyz="0.097227 0.097227 -0.008375"
      rpy="-3.9119E-18 -4.0687E-16 0.7854" />
    <parent
      link="Body" />
    <child
      link="Limb1_shoulder" />
    <axis
      xyz="0 0 1" />
    <limit
      lower="-3.1415"
      upper="3.1415"
      effort="0"
      velocity="0" />
  </joint>
  <link
    name="Limb1_femur">
    <inertial>
      <origin
        xyz="0.12027 -0.0014628 8.4845E-05"
        rpy="0 0 0" />
      <mass
        value="0.46337" />
      <inertia
        ixx="0.00021908"
        ixy="-5.5009E-05"
        ixz="5.6361E-06"
        iyy="0.0076055"
        iyz="9.3972E-07"
        izz="0.0076974" />
    </inertial>
    <visual>
      <origin
        xyz="0 0 0"
        rpy="0 0 0" />
      <geometry>
        <mesh
          filename="package://ALPHRED/meshes/Limb1_femur.STL" />
      </geometry>
      <material
        name="">
        <color
          rgba="0.75294 0.75294 0.75294 1" />
      </material>
    </visual>
    <collision>
      <origin
        xyz="0 0 0"
        rpy="0 0 0" />
      <geometry>
        <mesh
          filename="package://ALPHRED/meshes/Limb1_femur.STL" />
      </geometry>
    </collision>
  </link>
  <joint
    name="J2"
    type="revolute">
    <origin
      xyz="0.1025 0 0"
      rpy="-1.5708 -1.8691E-15 -7.7407E-15" />
    <parent
      link="Limb1_shoulder" />
    <child
      link="Limb1_femur" />
    <axis
      xyz="0 0 1" />
    <limit
      lower="-3.1415"
      upper="3.1415"
      effort="0"
      velocity="0" />
  </joint>
  <link
    name="Limb1_tibia">
    <inertial>
      <origin
        xyz="0.199106037929234 -5.18175489279127E-05 -0.00595341382921875"
        rpy="0 0 0" />
      <mass
        value="0.435212940847427" />
      <inertia
        ixx="0.000340932819483834"
        ixy="1.86296591266478E-06"
        ixz="-0.00026239332756004"
        iyy="0.00638026928825332"
        iyz="1.9998215512662E-07"
        izz="0.00608669935784455" />
    </inertial>
    <visual>
      <origin
        xyz="0 0 0"
        rpy="0 0 0" />
      <geometry>
        <mesh
          filename="package://ALPHRED/meshes/Limb1_tibia.STL" />
      </geometry>
      <material
        name="">
        <color
          rgba="0.752941176470588 0.752941176470588 0.752941176470588 1" />
      </material>
    </visual>
    <collision>
      <origin
        xyz="0 0 0"
        rpy="0 0 0" />
      <geometry>
        <mesh
          filename="package://ALPHRED/meshes/Limb1_tibia.STL" />
      </geometry>
    </collision>
  </link>
  <joint
    name="J3"
    type="revolute">
    <origin
      xyz="0.35 0 0.00125"
      rpy="3.9883E-16 4.2543E-16 2.093E-15" />
    <parent
      link="Limb1_femur" />
    <child
      link="Limb1_tibia" />
    <axis
      xyz="0 0 1" />
    <limit
      lower="-3.1415"
      upper="3.1415"
      effort="0"
      velocity="0" />
  </joint>
  <link
    name="Limb2_shoulder">
    <inertial>
      <origin
        xyz="0.060229 3.2889E-05 0.0007757"
        rpy="0 0 0" />
      <mass
        value="0.98609" />
      <inertia
        ixx="0.0021111"
        ixy="1.9535E-06"
        ixz="4.5886E-05"
        iyy="0.0030799"
        iyz="-4.1173E-06"
        izz="0.003987" />
    </inertial>
    <visual>
      <origin
        xyz="0 0 0"
        rpy="0 0 0" />
      <geometry>
        <mesh
          filename="package://ALPHRED/meshes/Limb2_shoulder.STL" />
      </geometry>
      <material
        name="">
        <color
          rgba="0.75294 0.75294 0.75294 1" />
      </material>
    </visual>
    <collision>
      <origin
        xyz="0 0 0"
        rpy="0 0 0" />
      <geometry>
        <mesh
          filename="package://ALPHRED/meshes/Limb2_shoulder.STL" />
      </geometry>
    </collision>
  </link>
  <joint
    name="J4"
    type="revolute">
    <origin
      xyz="-0.097227 0.097227 -0.008375"
      rpy="-7.8723E-18 9.6697E-17 2.3562" />
    <parent
      link="Body" />
    <child
      link="Limb2_shoulder" />
    <axis
      xyz="0 0 1" />
    <limit
      lower="-3.1415"
      upper="3.1415"
      effort="0"
      velocity="0" />
  </joint>
  <link
    name="Limb2_femur">
    <inertial>
      <origin
        xyz="0.120273609186976 -0.00146282253445634 8.48456980458772E-05"
        rpy="0 0 0" />
      <mass
        value="0.463365497341391" />
      <inertia
        ixx="0.000219083983228853"
        ixy="-5.50093728382085E-05"
        ixz="5.63610991530169E-06"
        iyy="0.0076054644050848"
        iyz="9.3972084549634E-07"
        izz="0.00769738894637063" />
    </inertial>
    <visual>
      <origin
        xyz="0 0 0"
        rpy="0 0 0" />
      <geometry>
        <mesh
          filename="package://ALPHRED/meshes/Limb2_femur.STL" />
      </geometry>
      <material
        name="">
        <color
          rgba="0.752941176470588 0.752941176470588 0.752941176470588 1" />
      </material>
    </visual>
    <collision>
      <origin
        xyz="0 0 0"
        rpy="0 0 0" />
      <geometry>
        <mesh
          filename="package://ALPHRED/meshes/Limb2_femur.STL" />
      </geometry>
    </collision>
  </link>
  <joint
    name="J5"
    type="revolute">
    <origin
      xyz="0.1025 0 0"
      rpy="-1.5708 -1.8765E-15 -2.9881E-16" />
    <parent
      link="Limb2_shoulder" />
    <child
      link="Limb2_femur" />
    <axis
      xyz="0 0 1" />
    <limit
      lower="-3.1415"
      upper="3.1415"
      effort="0"
      velocity="0" />
  </joint>
  <link
    name="Limb2_tibia">
    <inertial>
      <origin
        xyz="0.199206681201459 5.18446410381068E-05 0.00372142562269639"
        rpy="0 0 0" />
      <mass
        value="0.434987865778717" />
      <inertia
        ixx="0.000339805556175801"
        ixy="-1.86071690165809E-06"
        ixz="0.000285618971469065"
        iyy="0.00637062245479408"
        iyz="2.0345073166496E-07"
        izz="0.00607817923452022" />
    </inertial>
    <visual>
      <origin
        xyz="0 0 0"
        rpy="0 0 0" />
      <geometry>
        <mesh
          filename="package://ALPHRED/meshes/Limb2_tibia.STL" />
      </geometry>
      <material
        name="">
        <color
          rgba="0.752941176470588 0.752941176470588 0.752941176470588 1" />
      </material>
    </visual>
    <collision>
      <origin
        xyz="0 0 0"
        rpy="0 0 0" />
      <geometry>
        <mesh
          filename="package://ALPHRED/meshes/Limb2_tibia.STL" />
      </geometry>
    </collision>
  </link>
  <joint
    name="J6"
    type="revolute">
    <origin
      xyz="0.35 0 0.00125"
      rpy="5.3385E-16 1.2128E-16 1.5023E-15" />
    <parent
      link="Limb2_femur" />
    <child
      link="Limb2_tibia" />
    <axis
      xyz="0 0 1" />
    <limit
      lower="-3.1415"
      upper="3.1415"
      effort="0"
      velocity="0" />
  </joint>
  <link
    name="Limb3_shoulder">
    <inertial>
      <origin
        xyz="0.060229 3.2883E-05 0.0007757"
        rpy="0 0 0" />
      <mass
        value="0.98609" />
      <inertia
        ixx="0.0021111"
        ixy="1.9536E-06"
        ixz="4.5886E-05"
        iyy="0.0030799"
        iyz="-4.1174E-06"
        izz="0.003987" />
    </inertial>
    <visual>
      <origin
        xyz="0 0 0"
        rpy="0 0 0" />
      <geometry>
        <mesh
          filename="package://ALPHRED/meshes/Limb3_shoulder.STL" />
      </geometry>
      <material
        name="">
        <color
          rgba="0.75294 0.75294 0.75294 1" />
      </material>
    </visual>
    <collision>
      <origin
        xyz="0 0 0"
        rpy="0 0 0" />
      <geometry>
        <mesh
          filename="package://ALPHRED/meshes/Limb3_shoulder.STL" />
      </geometry>
    </collision>
  </link>
  <joint
    name="J7"
    type="revolute">
    <origin
      xyz="-0.097227 -0.097227 -0.008375"
      rpy="0 9.3453E-17 -2.3562" />
    <parent
      link="Body" />
    <child
      link="Limb3_shoulder" />
    <axis
      xyz="0 0 1" />
    <limit
      lower="-3.1415"
      upper="3.1415"
      effort="0"
      velocity="0" />
  </joint>
  <link
    name="Limb3_femur">
    <inertial>
      <origin
        xyz="0.12027 -0.0014628 8.4846E-05"
        rpy="0 0 0" />
      <mass
        value="0.46337" />
      <inertia
        ixx="0.00021908"
        ixy="-5.5009E-05"
        ixz="5.6361E-06"
        iyy="0.0076055"
        iyz="9.3972E-07"
        izz="0.0076974" />
    </inertial>
    <visual>
      <origin
        xyz="0 0 0"
        rpy="0 0 0" />
      <geometry>
        <mesh
          filename="package://ALPHRED/meshes/Limb3_femur.STL" />
      </geometry>
      <material
        name="">
        <color
          rgba="0.75294 0.75294 0.75294 1" />
      </material>
    </visual>
    <collision>
      <origin
        xyz="0 0 0"
        rpy="0 0 0" />
      <geometry>
        <mesh
          filename="package://ALPHRED/meshes/Limb3_femur.STL" />
      </geometry>
    </collision>
  </link>
  <joint
    name="J8"
    type="revolute">
    <origin
      xyz="0.1025 0 0"
      rpy="-1.5708 -1.9531E-15 -4.3469E-16" />
    <parent
      link="Limb3_shoulder" />
    <child
      link="Limb3_femur" />
    <axis
      xyz="0 0 1" />
    <limit
      lower="-3.1415"
      upper="3.1415"
      effort="0"
      velocity="0" />
  </joint>
  <link
    name="Limb3_tibia">
    <inertial>
      <origin
        xyz="0.199105981821244 -5.18181173335547E-05 -0.00595341111180384"
        rpy="0 0 0" />
      <mass
        value="0.435213066234179" />
      <inertia
        ixx="0.00034093285413351"
        ixy="1.86296244733014E-06"
        ixz="-0.00026239298861417"
        iyy="0.00638027416368471"
        iyz="1.99976103390854E-07"
        izz="0.00608670420966022" />
    </inertial>
    <visual>
      <origin
        xyz="0 0 0"
        rpy="0 0 0" />
      <geometry>
        <mesh
          filename="package://ALPHRED/meshes/Limb3_tibia.STL" />
      </geometry>
      <material
        name="">
        <color
          rgba="0.752941176470588 0.752941176470588 0.752941176470588 1" />
      </material>
    </visual>
    <collision>
      <origin
        xyz="0 0 0"
        rpy="0 0 0" />
      <geometry>
        <mesh
          filename="package://ALPHRED/meshes/Limb3_tibia.STL" />
      </geometry>
    </collision>
  </link>
  <joint
    name="J9"
    type="revolute">
    <origin
      xyz="0.35 0 0.00125"
      rpy="2.5633E-16 5.0599E-16 2.1372E-15" />
    <parent
      link="Limb3_femur" />
    <child
      link="Limb3_tibia" />
    <axis
      xyz="0 0 1" />
    <limit
      lower="-3.1415"
      upper="3.1415"
      effort="0"
      velocity="0" />
  </joint>
  <link
    name="Limb4_shoulder">
    <inertial>
      <origin
        xyz="0.0602294589071593 3.28852494247649E-05 0.000775699264374763"
        rpy="0 0 0" />
      <mass
        value="0.986086827865671" />
      <inertia
        ixx="0.00211105369898595"
        ixy="1.95346480655161E-06"
        ixz="4.58861785293303E-05"
        iyy="0.00307989494240472"
        iyz="-4.11725899101511E-06"
        izz="0.00398699595045447" />
    </inertial>
    <visual>
      <origin
        xyz="0 0 0"
        rpy="0 0 0" />
      <geometry>
        <mesh
          filename="package://ALPHRED/meshes/Limb4_shoulder.STL" />
      </geometry>
      <material
        name="">
        <color
          rgba="0.752941176470588 0.752941176470588 0.752941176470588 1" />
      </material>
    </visual>
    <collision>
      <origin
        xyz="0 0 0"
        rpy="0 0 0" />
      <geometry>
        <mesh
          filename="package://ALPHRED/meshes/Limb4_shoulder.STL" />
      </geometry>
    </collision>
  </link>
  <joint
    name="J10"
    type="revolute">
    <origin
      xyz="0.097227 -0.097227 -0.008375"
      rpy="-9.7093E-18 1.4153E-16 -0.7854" />
    <parent
      link="Body" />
    <child
      link="Limb4_shoulder" />
    <axis
      xyz="0 0 1" />
    <limit
      lower="-3.1415"
      upper="3.1415"
      effort="0"
      velocity="0" />
  </joint>
  <link
    name="Limb4_femur">
    <inertial>
      <origin
        xyz="0.120273608293698 -0.0014628225200454 8.48455579533397E-05"
        rpy="0 0 0" />
      <mass
        value="0.46336550119893" />
      <inertia
        ixx="0.000219083984329474"
        ixy="-5.50093721251035E-05"
        ixz="5.6361029512727E-06"
        iyy="0.00760546445059367"
        iyz="9.3972095759372E-07"
        izz="0.00769738899079005" />
    </inertial>
    <visual>
      <origin
        xyz="0 0 0"
        rpy="0 0 0" />
      <geometry>
        <mesh
          filename="package://ALPHRED/meshes/Limb4_femur.STL" />
      </geometry>
      <material
        name="">
        <color
          rgba="0.752941176470588 0.752941176470588 0.752941176470588 1" />
      </material>
    </visual>
    <collision>
      <origin
        xyz="0 0 0"
        rpy="0 0 0" />
      <geometry>
        <mesh
          filename="package://ALPHRED/meshes/Limb4_femur.STL" />
      </geometry>
    </collision>
  </link>
  <joint
    name="J11"
    type="revolute">
    <origin
      xyz="0.1025 0 0"
      rpy="-1.5708 -2.0844E-15 -1.1117E-16" />
    <parent
      link="Limb4_shoulder" />
    <child
      link="Limb4_femur" />
    <axis
      xyz="0 0 1" />
    <limit
      lower="-3.1415"
      upper="3.1415"
      effort="0"
      velocity="0" />
  </joint>
  <link
    name="Limb4_tibia">
    <inertial>
      <origin
        xyz="0.19921 5.1846E-05 0.0037214"
        rpy="0 0 0" />
      <mass
        value="0.43499" />
      <inertia
        ixx="0.00033981"
        ixy="-1.8608E-06"
        ixz="0.00028562"
        iyy="0.0063706"
        iyz="2.0344E-07"
        izz="0.0060782" />
    </inertial>
    <visual>
      <origin
        xyz="0 0 0"
        rpy="0 0 0" />
      <geometry>
        <mesh
          filename="package://ALPHRED/meshes/Limb4_tibia.STL" />
      </geometry>
      <material
        name="">
        <color
          rgba="0.75294 0.75294 0.75294 1" />
      </material>
    </visual>
    <collision>
      <origin
        xyz="0 0 0"
        rpy="0 0 0" />
      <geometry>
        <mesh
          filename="package://ALPHRED/meshes/Limb4_tibia.STL" />
      </geometry>
    </collision>
  </link>
  <joint
    name="J12"
    type="fixed">
    <origin
      xyz="0.35 0 0.00125"
      rpy="3.8324E-16 4.2659E-16 1.6653E-15" />
    <parent
      link="Limb4_femur" />
    <child
      link="Limb4_tibia" />
    <axis
      xyz="0 0 1" />
    <limit
      lower="-3.1415"
      upper="3.1415"
      effort="0"
      velocity="0" />
  </joint>
</robot>
